<?xml version="1.0"?>
<robot xmlns:xacro="http://www.ros.org/wiki/xacro">
    <xacro:property name="distance_to_roller_center" value="0.063"/>

    <xacro:macro name="inertial_cylinder" params="mass length radius *origin">
        <inertial>
            <xacro:insert_block name="origin"/>
            <mass value="${mass}" />
            <inertia 
                ixx="${(1/12) * mass * (3*radius*radius + length*length)}"
                ixy="0.0"
                ixz="0.0"
                iyy="${(1/12) * mass * (3*radius*radius + length*length)}"
                iyz="0.0"
                izz="${(1/2) * mass * (radius*radius)}" />
            </inertial>
    </xacro:macro>

    <xacro:macro name="insert_roller" params="parent reflect theta suffix wheel">
        <joint name="rim_to_roller${wheel}${suffix}joint" type="continuous">
            <origin xyz="${distance_to_roller_center*cos(theta)} ${distance_to_roller_center*sin(theta)} ${reflect*0.008}" rpy="0.0 0.0 ${theta-pi/2}"/>
            <parent link="${parent}"/>
            <child link="roller${wheel}${suffix}_link"/>
            <axis xyz="1.0 0.0 0.0"/>
            <dynamics friction="0.1"/>
        </joint>

        <link name="roller${wheel}${suffix}_link">
            <visual>
                <origin xyz="-0.007 0.0 0.0" rpy="0.0 ${pi/2} 0"/>
                <geometry>
                    <mesh filename="file://$(find arceus_description)/meshes/roleteteste.stl" scale="0.001 0.001 0.001"/>
                </geometry>
                <material name="green"/>
            </visual>

            <collision>
                <origin xyz="0.0 0.0 0.0" rpy="0.0 0.0 0.0"/>
                <geometry>
                    <mesh filename="file://$(find arceus_description)/meshes/roleteteste.stl"/>
                </geometry>
            </collision>

            <inertial>
                <origin xyz="0.0 0.0 0.0" rpy="0.0 0.0 0.0"/>
                <mass value="0.003"/>
                <inertia ixx="5.3e-8"
                         ixy="0.0"
                         ixz="0.0"
                         iyy="8e-8"
                         iyz="0.0"
                         izz="8e-8"/>
            </inertial>
        </link>
        <gazebo reference="roller${wheel}${suffix}_link">
            <material>Gazebo/Green</material>
            <fdir1>1 0 0"</fdir1>
            <mu1>100</mu1>
            <mu2>100</mu2>
            <minDepth>0.001</minDepth>
        </gazebo>
    </xacro:macro>

    <xacro:macro name="wheel" params="parent suffix theta m r h">
        <joint name="wheel${suffix}_shaft_joint" type="fixed">
            <origin xyz="${base_radius*cos(theta)} ${base_radius*sin(theta)} -${base_width/1.95}" rpy="0.0 ${pi/2} ${theta+pi}"/>
            <parent link="${parent}"/>
            <child link="motor${suffix}_shaft_link"/>
        </joint>

        <link name="motor${suffix}_shaft_link">
            <visual>
                <origin xyz="0.0 0.0 -${motor_shaft_length/2}" rpy="0.0 0.0 0.0"/>
                <geometry>
                    <cylinder radius="${motor_shaft_radius}" length="${motor_shaft_length}"/>
                </geometry>
            </visual>

            <collision>
                <origin xyz="0.0 0.0 -${motor_shaft_length/2}" rpy="0.0 0.0 0.0"/>
                <geometry>
                    <cylinder radius="${motor_shaft_radius}" length="${motor_shaft_length}"/>
                </geometry>
            </collision>
            <xacro:inertial_cylinder mass="${shaft_mass}" radius="${motor_shaft_radius}" length="${motor_shaft_length}">
                <origin xyz="0.0 0.0 -${motor_shaft_length/2}" rpy="0.0 0.0 0.0"/>
            </xacro:inertial_cylinder>
        </link>

        <joint name="wheel${suffix}_joint" type="continuous">
            <origin xyz="0.0 0.0 -${motor_shaft_length+wheel_width/2}" rpy="0.0 0.0 0.0"/>
            <parent link="motor${suffix}_shaft_link"/>
            <child link="wheel${suffix}_link"/>
            <axis xyz="0.0 0.0 1.0"/>
        </joint>

        <link name="wheel${suffix}_link">
            <visual>
                <origin xyz="0.0 0.0 0.0" rpy="0.0 0.0 0.0"/>
                <geometry>
                    <!-- <mesh filename="file://$(find arceus_description)/meshes/rodateste.stl" scale="0.001 0.001 0.001"/> -->
                    <cylinder radius="${wheel_radius}" length="${wheel_width}"/>
                </geometry>
            </visual>

            <collision>
                <origin xyz="0.0 0.0 0.0" rpy="0.0 0.0 0.0"/>
                <geometry>
                    <!-- <mesh filename="file://$(find zeus_description)/meshes/wheel-collision.dae"/> -->
                    <cylinder radius="${wheel_radius}" length="${wheel_width}"/>
                </geometry>
            </collision>

            <inertial>
                <origin xyz="0.0 0.0 0.0" rpy="0.0 0.0 0.0"/>
                <mass value="${m}"/>
			    <inertia ixx="${(m/12) * (3*r*r + h*h)}" ixy = "0" ixz = "0" iyy="${(m/12) * (3*r*r + h*h)}" iyz = "0" izz="${(m/2) * (r*r)}"/>
            </inertial>
        </link>

        <!-- <xacro:insert_roller parent="wheel${suffix}_link" reflect="1.0" theta="${3*pi/10}" suffix="1" wheel="${suffix}"/>
        <xacro:insert_roller parent="wheel${suffix}_link" reflect="1.0" theta="${13*pi/30}" suffix="2" wheel="${suffix}"/>
        <xacro:insert_roller parent="wheel${suffix}_link" reflect="1.0" theta="${17*pi/30}" suffix="3" wheel="${suffix}"/>
        <xacro:insert_roller parent="wheel${suffix}_link" reflect="1.0" theta="${7*pi/10}" suffix="4" wheel="${suffix}"/>
        <xacro:insert_roller parent="wheel${suffix}_link" reflect="1.0" theta="${5*pi/6}" suffix="5" wheel="${suffix}"/>
        <xacro:insert_roller parent="wheel${suffix}_link" reflect="1.0" theta="${29*pi/30}" suffix="6" wheel="${suffix}"/>
        <xacro:insert_roller parent="wheel${suffix}_link" reflect="1.0" theta="${11*pi/10}" suffix="7" wheel="${suffix}"/>
        <xacro:insert_roller parent="wheel${suffix}_link" reflect="1.0" theta="${37*pi/30}" suffix="8" wheel="${suffix}"/>
        <xacro:insert_roller parent="wheel${suffix}_link" reflect="1.0" theta="${41*pi/30}" suffix="9" wheel="${suffix}"/>
        <xacro:insert_roller parent="wheel${suffix}_link" reflect="1.0" theta="${3*pi/2}" suffix="10" wheel="${suffix}"/>
        <xacro:insert_roller parent="wheel${suffix}_link" reflect="1.0" theta="${49*pi/30}" suffix="11" wheel="${suffix}"/>
        <xacro:insert_roller parent="wheel${suffix}_link" reflect="1.0" theta="${53*pi/30}" suffix="12" wheel="${suffix}"/>
        <xacro:insert_roller parent="wheel${suffix}_link" reflect="1.0" theta="${19*pi/10}" suffix="13" wheel="${suffix}"/>
        <xacro:insert_roller parent="wheel${suffix}_link" reflect="1.0" theta="${61*pi/30}" suffix="14" wheel="${suffix}"/>
        <xacro:insert_roller parent="wheel${suffix}_link" reflect="1.0" theta="${13*pi/6}" suffix="15" wheel="${suffix}"/> -->

        <!-- <xacro:insert_roller parent="wheel${suffix}_link" reflect="-1.0" theta="${45*pi/180}" suffix="-1" wheel="${suffix}"/>
        <xacro:insert_roller parent="wheel${suffix}_link" reflect="-1.0" theta="${75*pi/180}" suffix="-2" wheel="${suffix}"/>
        <xacro:insert_roller parent="wheel${suffix}_link" reflect="-1.0" theta="${105*pi/180}" suffix="-3" wheel="${suffix}"/>
        <xacro:insert_roller parent="wheel${suffix}_link" reflect="-1.0" theta="${135*pi/180}" suffix="-4" wheel="${suffix}"/>
        <xacro:insert_roller parent="wheel${suffix}_link" reflect="-1.0" theta="${165*pi/180}" suffix="-5" wheel="${suffix}"/>
        <xacro:insert_roller parent="wheel${suffix}_link" reflect="-1.0" theta="${195*pi/180}" suffix="-6" wheel="${suffix}"/>
        <xacro:insert_roller parent="wheel${suffix}_link" reflect="-1.0" theta="${225*pi/180}" suffix="-7" wheel="${suffix}"/>
        <xacro:insert_roller parent="wheel${suffix}_link" reflect="-1.0" theta="${255*pi/180}" suffix="-8" wheel="${suffix}"/>
        <xacro:insert_roller parent="wheel${suffix}_link" reflect="-1.0" theta="${285*pi/180}" suffix="-9" wheel="${suffix}"/>
        <xacro:insert_roller parent="wheel${suffix}_link" reflect="-1.0" theta="${315*pi/180}" suffix="-10" wheel="${suffix}"/>
        <xacro:insert_roller parent="wheel${suffix}_link" reflect="-1.0" theta="${345*pi/180}" suffix="-11" wheel="${suffix}"/>
        <xacro:insert_roller parent="wheel${suffix}_link" reflect="-1.0" theta="${375*pi/180}" suffix="-12" wheel="${suffix}"/> -->
    </xacro:macro>
</robot>