<?xml version="1.0"?>
<robot xmlns:xacro="http://www.ros.org/wiki/xacro">
    <xacro:property name="distance_to_roller_center" value="0.063"/>

    <xacro:macro name="inertial_cylinder" params="mass length radius *origin">
        <inertial>
            <xacro:insert_block name="origin"/>
            <mass value="${mass}" />
            <inertia 
                ixx="${(1/12) * mass * (3*radius*radius + length*length)}"
                ixy="0.0"
                ixz="0.0"
                iyy="${(1/12) * mass * (3*radius*radius + length*length)}"
                iyz="0.0"
                izz="${(1/2) * mass * (radius*radius)}" />
            </inertial>
    </xacro:macro>

    <xacro:macro name="insert_roller" params="parent reflect theta suffix wheel">
        <joint name="rim_to_roller_${wheel}_${suffix}_joint" type="continuous">
            <origin xyz="${distance_to_roller_center*cos(theta)} ${distance_to_roller_center*sin(theta)} ${reflect*0.008}" rpy="0.0 0.0 ${theta-pi/2}"/>
            <parent link="${parent}"/>
            <child link="roller_${wheel}_${suffix}_link"/>
            <axis xyz="1.0 0.0 0.0"/>
        </joint>

        <link name="roller_${wheel}_${suffix}_link">
            <visual>
                <origin xyz="0.0 0.0 0.0" rpy="0.0 ${pi/2} 0"/>
                <geometry>
                    <cylinder radius="0.008" length="0.0125"/>
                </geometry>
            </visual>

            <collision>
                <origin xyz="0.0 0.0 0.0" rpy="0.0 ${pi/2} 0.0"/>
                <geometry>
                    <cylinder radius="0.008" length="0.0125"/>
                </geometry>
            </collision>
            <xacro:inertial_cylinder mass="${0.08}" radius="0.008" length="0.0125">
                <origin xyz="0.0 0.0 0.0" rpy="0.0 ${pi/2} 0.0"/>
            </xacro:inertial_cylinder>
        </link>
        <gazebo reference="roller_${wheel}_${suffix}_link">
            <fdir1>1 0 0</fdir1>
            <mu1>100</mu1>
            <mu2>100</mu2>
            <minDepth>0.001</minDepth>
        </gazebo>
    </xacro:macro>

    <xacro:macro name="wheel" params="parent suffix theta m r h">
        <joint name="wheel_${suffix}_shaft_joint" type="fixed">
            <origin xyz="${base_radius*cos(theta)} ${base_radius*sin(theta)} -${base_width/1.95}" rpy="0.0 ${pi/2} ${theta+pi}"/>
            <parent link="${parent}"/>
            <child link="motor_${suffix}_shaft_link"/>
        </joint>

        <link name="motor_${suffix}_shaft_link">
            <visual>
                <origin xyz="0.0 0.0 -${motor_shaft_length/2}" rpy="0.0 0.0 0.0"/>
                <geometry>
                    <cylinder radius="${motor_shaft_radius}" length="${motor_shaft_length}"/>
                </geometry>
            </visual>

            <collision>
                <origin xyz="0.0 0.0 -${motor_shaft_length/2}" rpy="0.0 0.0 0.0"/>
                <geometry>
                    <cylinder radius="${motor_shaft_radius}" length="${motor_shaft_length}"/>
                </geometry>
            </collision>
            <xacro:inertial_cylinder mass="${shaft_mass}" radius="${motor_shaft_radius}" length="${motor_shaft_length}">
                <origin xyz="0.0 0.0 -${motor_shaft_length/2}" rpy="0.0 0.0 0.0"/>
            </xacro:inertial_cylinder>
        </link>

        <joint name="wheel${suffix}_joint" type="continuous">
            <origin xyz="0.0 0.0 -${motor_shaft_length+wheel_width}" rpy="0.0 0.0 0.0"/>
            <parent link="motor_${suffix}_shaft_link"/>
            <child link="wheel${suffix}_link"/>
            <axis xyz="0.0 0.0 1.0"/>
        </joint>

        <link name="wheel${suffix}_link">
            <visual>
                <origin xyz="0.0 0.0 0.0" rpy="0.0 0.0 0.0"/>
                <geometry>
                    <xacro:if value="$(arg use_omni_wheels)">
                        <mesh filename="file://$(find arceus_description)/meshes/rodateste.stl" scale="0.001 0.001 0.001"/>
                    </xacro:if>
                    <xacro:unless value="$(arg use_omni_wheels)">
                        <cylinder radius="${wheel_radius}" length="${wheel_width}"/>
                    </xacro:unless>
                </geometry>
            </visual>

            <collision>
                <origin xyz="0.0 0.0 0.0" rpy="0.0 0.0 0.0"/>
                <geometry>
                    <xacro:if value="$(arg use_omni_wheels)">
                        <!-- <mesh filename="file://$(find arceus_description)/meshes/rodateste.stl" scale="0.001 0.001 0.001"/> -->
                        <cylinder radius="${wheel_radius}" length="${wheel_width}"/>
                    </xacro:if>
                    <xacro:unless value="$(arg use_omni_wheels)">
                        <cylinder radius="${wheel_radius}" length="${wheel_width}"/>
                    </xacro:unless>
                </geometry>
            </collision>
            <xacro:inertial_cylinder mass="${m}" radius="${r}" length="${h}">
                <origin xyz="0.0 0.0 0.012" rpy="0.0 0 0.0"/>
            </xacro:inertial_cylinder>
        </link>

        <xacro:if value="$(arg use_omni_wheels)">
            <xacro:insert_roller parent="wheel${suffix}_link" reflect="0.7" theta="${3*pi/10}" suffix="1" wheel="${suffix}"/>
            <xacro:insert_roller parent="wheel${suffix}_link" reflect="0.7" theta="${13*pi/30}" suffix="2" wheel="${suffix}"/>
            <xacro:insert_roller parent="wheel${suffix}_link" reflect="0.7" theta="${17*pi/30}" suffix="3" wheel="${suffix}"/>
            <xacro:insert_roller parent="wheel${suffix}_link" reflect="0.7" theta="${7*pi/10}" suffix="4" wheel="${suffix}"/>
            <xacro:insert_roller parent="wheel${suffix}_link" reflect="0.7" theta="${5*pi/6}" suffix="5" wheel="${suffix}"/>
            <xacro:insert_roller parent="wheel${suffix}_link" reflect="0.7" theta="${29*pi/30}" suffix="6" wheel="${suffix}"/>
            <xacro:insert_roller parent="wheel${suffix}_link" reflect="0.7" theta="${11*pi/10}" suffix="7" wheel="${suffix}"/>
            <xacro:insert_roller parent="wheel${suffix}_link" reflect="0.7" theta="${37*pi/30}" suffix="8" wheel="${suffix}"/>
            <xacro:insert_roller parent="wheel${suffix}_link" reflect="0.7" theta="${41*pi/30}" suffix="9" wheel="${suffix}"/>
            <xacro:insert_roller parent="wheel${suffix}_link" reflect="0.7" theta="${3*pi/2}" suffix="10" wheel="${suffix}"/>
            <xacro:insert_roller parent="wheel${suffix}_link" reflect="0.7" theta="${49*pi/30}" suffix="11" wheel="${suffix}"/>
            <xacro:insert_roller parent="wheel${suffix}_link" reflect="0.7" theta="${53*pi/30}" suffix="12" wheel="${suffix}"/>
            <xacro:insert_roller parent="wheel${suffix}_link" reflect="0.7" theta="${19*pi/10}" suffix="13" wheel="${suffix}"/>
            <xacro:insert_roller parent="wheel${suffix}_link" reflect="0.7" theta="${61*pi/30}" suffix="14" wheel="${suffix}"/>
            <xacro:insert_roller parent="wheel${suffix}_link" reflect="0.7" theta="${13*pi/6}" suffix="15" wheel="${suffix}"/>

            <xacro:insert_roller parent="wheel${suffix}_link" reflect="3.0" theta="${-3*pi/2}" suffix="-1" wheel="${suffix}"/>
            <xacro:insert_roller parent="wheel${suffix}_link" reflect="3.0" theta="${-49*pi/30}" suffix="-2" wheel="${suffix}"/>
            <xacro:insert_roller parent="wheel${suffix}_link" reflect="3.0" theta="${-53*pi/30}" suffix="-3" wheel="${suffix}"/>
            <xacro:insert_roller parent="wheel${suffix}_link" reflect="3.0" theta="${-19*pi/10}" suffix="-4" wheel="${suffix}"/>
            <xacro:insert_roller parent="wheel${suffix}_link" reflect="3.0" theta="${-61*pi/30}" suffix="-5" wheel="${suffix}"/>
            <xacro:insert_roller parent="wheel${suffix}_link" reflect="3.0" theta="${-13*pi/6}" suffix="-6" wheel="${suffix}"/>
            <xacro:insert_roller parent="wheel${suffix}_link" reflect="3.0" theta="${-3*pi/10}" suffix="-7" wheel="${suffix}"/>
            <xacro:insert_roller parent="wheel${suffix}_link" reflect="3.0" theta="${-13*pi/30}" suffix="-8" wheel="${suffix}"/>
            <xacro:insert_roller parent="wheel${suffix}_link" reflect="3.0" theta="${-17*pi/30}" suffix="-9" wheel="${suffix}"/>
            <xacro:insert_roller parent="wheel${suffix}_link" reflect="3.0" theta="${-7*pi/10}" suffix="-10" wheel="${suffix}"/>
            <xacro:insert_roller parent="wheel${suffix}_link" reflect="3.0" theta="${-5*pi/6}" suffix="-11" wheel="${suffix}"/>
            <xacro:insert_roller parent="wheel${suffix}_link" reflect="3.0" theta="${-29*pi/30}" suffix="-12" wheel="${suffix}"/>
            <xacro:insert_roller parent="wheel${suffix}_link" reflect="3.0" theta="${-11*pi/10}" suffix="-13" wheel="${suffix}"/>
            <xacro:insert_roller parent="wheel${suffix}_link" reflect="3.0" theta="${-37*pi/30}" suffix="-14" wheel="${suffix}"/>
            <xacro:insert_roller parent="wheel${suffix}_link" reflect="3.0" theta="${-41*pi/30}" suffix="-15" wheel="${suffix}"/>
        </xacro:if>
    </xacro:macro>
</robot>